Workbook

Sheet Summary
A1: LeetCode history: list "Anuj Mar-23 to present"
A2: Pulled from LeetCode on 2026-10-24 12:43 IST. Times are IST.
A4: Your list
A5: Problems in the list | B5: =COUNTA('Solved Problems'!$C$2:$C$278)
A6: Solved (LeetCode status) | B6: =COUNTIF('Solved Problems'!$I$2:$I$278,"Solved")
A7: Attempted, not solved | B7: =COUNTIF('Solved Problems'!$I$2:$I$278,"Attempted")
A8: Easy | B8: =COUNTIF('Solved Problems'!$D$2:$D$278,"Easy")
A9: Medium | B9: =COUNTIF('Solved Problems'!$D$2:$D$278,"Medium")
A10: Hard | B10: =COUNTIF('Solved Problems'!$D$2:$D$278,"Hard")
A11: Solved on the first submission | B11: =COUNTIF('Solved Problems'!$P$2:$P$278,"Yes")
A12: First-try AC rate | B12: =B11/B5
A13: Patterns covered | B13: =COUNTIF('Pattern Summary'!$F$2:$F$36,">0") | C13: out of 35 patterns in this workbook
A14: Submissions
A15: Submissions since Mar 2023 (list + other) | B15: =COUNTA(Submissions!$A$2:$A$1621)
A16: of which on your list | B16: =COUNTIF(Submissions!$N$2:$N$1621,"Yes")
A17: Accepted | B17: =COUNTIF(Submissions!$G$2:$G$1621,"Accepted")
A18: Acceptance rate | B18: =B17/B15
A19: Wrong Answer | B19: =COUNTIF(Submissions!$G$2:$G$1621,"Wrong Answer")
A20: Time Limit Exceeded | B20: =COUNTIF(Submissions!$G$2:$G$1621,"Time Limit Exceeded")
A21: Runtime Error | B21: =COUNTIF(Submissions!$G$2:$G$1621,"Runtime Error")
A22: C++ submissions | B22: =COUNTIF(Submissions!$H$2:$H$1621,"C++")
A23: Python submissions | B23: =COUNTIF(Submissions!$H$2:$H$1621,"Python3")+COUNTIF(Submissions!$H$2:$H$1621,"Python")
A24: First submission | B24: =MIN(Submissions!$A$2:$A$1621)
A25: Latest submission | B25: =MAX(Submissions!$A$2:$A$1621)
A26: Other problems (account, not in list) | B26: =COUNTA('Other Problems'!$C$2:$C$119) | C26: Solved on this account since Mar 2023 but not in your list. Mark them Y/N on that sheet.
A27: Notes
A28: Whose work counts | C28: Only submissions from 1 Mar 2023 onward are counted (the list is named "Mar-23 to present"). Older submissions on these problems are counted in the 'Pre-Mar-2023 subs (excluded)' column.
A29: Submission links | C29: Submission links open only when you are signed in to the LeetCode account that made them.
A30: Code | C30: Every attempt's code, oldest first, is in the code/ folder next to this file, one Markdown file per problem.
A31: Patterns | C31: Pattern and sub-pattern are assigned by hand from how the problem is usually solved, not taken from LeetCode tags.
A32: Runtime beats % | C32: LeetCode recomputes this against today's runtimes, so 2023-era submissions often show near 0%. Compare within a problem, not across years.

Sheet Solved Problems
A1: # | B1: LC # | C1: Problem | D1: Difficulty | E1: Pattern | F1: Sub-pattern | G1: Topic group | H1: LeetCode tags | I1: LC status | J1: First attempt | K1: First accepted | L1: Last submission | M1: Submissions | N1: Accepted | O1: Failed before first AC | P1: First-try AC? | Q1: Wrong Answer (before AC) | R1: TLE (before AC) | S1: Other errors (before AC) | T1: Languages | U1: Best runtime beats % | V1: Latest accepted submission | W1: Code & attempts file | X1: Pre-Mar-2023 subs (excluded) | Y1: First AC month
A2: 1 | B2: 1 | C2: Two Sum | D2: Easy | E2: Arrays, Hashing & Sorting | F2: Complement map | G2: Arrays & Strings | H2: array, hash-table | I2: Solved | J2: 44991.912 | K2: 44991.912 | L2: 45218.859 | M2: 7 | N2: 7 | O2: 0 | P2: =IF(AND(N2>0,O2=0),"Yes","No") | Q2: 0 | R2: 0 | S2: 0 | T2: C++ | U2: 40.6 | V2: Submission 1079247546 | W2: Open code | X2: 2 | Y2: 2023-03
A3: 2 | B3: 13 | C3: Roman to Integer | D3: Easy | E3: Strings & Simulation | F3: Parsing | G3: Arrays & Strings | H3: hash-table, math, string | I3: Solved | J3: 44991.939 | K3: 44991.939 | L3: 44992.027 | M3: 2 | N3: 2 | O3: 0 | P3: =IF(AND(N3>0,O3=0),"Yes","No") | Q3: 0 | R3: 0 | S3: 0 | T3: C++ | U3: 26.4 | V3: Submission 910366895 | W3: Open code | X3: 0 | Y3: 2023-03
A4: 3 | B4: 14 | C4: Longest Common Prefix | D4: Easy | E4: Strings & Simulation | F4: Column scan | G4: Arrays & Strings | H4: array, string, trie | I4: Solved | J4: 44991.944 | K4: 44991.945 | L4: 44992.027 | M4: 3 | N4: 2 | O4: 1 | P4: =IF(AND(N4>0,O4=0),"Yes","No") | Q4: 1 | R4: 0 | S4: 0 | T4: C++ | U4: 100 | V4: Submission 910366984 | W4: Open code | X4: 0 | Y4: 2023-03
A5: 4 | B5: 20 | C5: Valid Parentheses | D5: Easy | E5: Stack | F5: Bracket matching | G5: Stacks & Queues | H5: string, stack, bracket-sequences | I5: Solved | J5: 44991.954 | K5: 44991.958 | L5: 45318.954 | M5: 5 | N5: 3 | O5: 2 | P5: =IF(AND(N5>0,O5=0),"Yes","No") | Q5: 1 | R5: 0 | S5: 1 | T5: C++, Python3 | U5: 3.7 | V5: Submission 1158444134 | W5: Open code | X5: 3 | Y5: 2023-03
A6: 5 | B6: 359 | C6: Logger Rate Limiter | D6: Easy | E6: Design | F6: Map of last timestamps | G6: Design | H6: hash-table, design, data-stream | I6: Solved | J6: 44991.99 | K6: 44991.99 | L6: 45042.68 | M6: 5 | N6: 5 | O6: 0 | P6: =IF(AND(N6>0,O6=0),"Yes","No") | Q6: 0 | R6: 0 | S6: 0 | T6: C++ | U6: 5.2 | V6: Submission 940009478 | W6: Open code | X6: 0 | Y6: 2023-03
A7: 6 | B7: 704 | C7: Binary Search | D7: Easy | E7: Binary Search | F7: Classic search | G7: Searching | H7: array, binary-search | I7: Solved | J7: 44992.004 | K7: 44992.004 | L7: 45243.974 | M7: 7 | N7: 5 | O7: 0 | P7: =IF(AND(N7>0,O7=0),"Yes","No") | Q7: 0 | R7: 0 | S7: 0 | T7: C++, Python3 | U7: 0.2 | V7: Submission 1098074392 | W7: Open code | X7: 3 | Y7: 2023-03
A8: 7 | B8: 938 | C8: Range Sum of BST | D8: Easy | E8: Binary Search Tree | F8: Range-pruned DFS | G8: Trees | H8: tree, depth-first-search, binary-search-tree, binary-tree | I8: Solved | J8: 44992.026 | K8: 44992.026 | L8: 45854.503 | M8: 13 | N8: 13 | O8: 0 | P8: =IF(AND(N8>0,O8=0),"Yes","No") | Q8: 0 | R8: 0 | S8: 0 | T8: C++, Python3 | U8: 100 | V8: Submission 1699707053 | W8: Open code | X8: 0 | Y8: 2023-03
A9: 8 | B9: 56 | C9: Merge Intervals | D9: Medium | E9: Intervals & Sweep Line | F9: Sort and merge | G9: Heaps & Intervals | H9: array, sorting, quicksort | I9: Solved | J9: 44992.071 | K9: 44992.071 | L9: 45845.963 | M9: 16 | N9: 12 | O9: 0 | P9: =IF(AND(N9>0,O9=0),"Yes","No") | Q9: 0 | R9: 0 | S9: 0 | T9: C++, Python, Python3 | U9: 90.8 | V9: Submission 1689875947 | W9: Open code | X9: 2 | Y9: 2023-03
A10: 9 | B10: 70 | C10: Climbing Stairs | D10: Easy | E10: DP: 1D / Linear | F10: Fibonacci | G10: Dynamic Programming | H10: math, dynamic-programming, memoization | I10: Solved | J10: 44996.411 | K10: 44996.411 | L10: 44996.411 | M10: 2 | N10: 1 | O10: 1 | P10: =IF(AND(N10>0,O10=0),"Yes","No") | Q10: 1 | R10: 0 | S10: 0 | T10: C++ | U10: 100 | V10: Submission 913014080 | W10: Open code | X10: 2 | Y10: 2023-03
A11: 10 | B11: 1377 | C11: Frog Position After T Seconds | D11: Hard | E11: Graph: General BFS/DFS | F11: BFS with probability | G11: Graphs | H11: tree, depth-first-search, breadth-first-search, graph | I11: Solved | J11: 44996.601 | K11: 44996.601 | L11: 44996.642 | M11: 2 | N11: 2 | O11: 0 | P11: =IF(AND(N11>0,O11=0),"Yes","No") | Q11: 0 | R11: 0 | S11: 0 | T11: C++ | U11: 11 | V11: Submission 913148665 | W11: Open code | X11: 0 | Y11: 2023-03
A12: 11 | B12: 213 | C12: House Robber II | D12: Medium | E12: DP: 1D / Linear | F12: Take/skip, circular | G12: Dynamic Programming | H12: array, dynamic-programming | I12: Solved | J12: 44996.71 | K12: 44996.712 | L12: 44996.712 | M12: 3 | N12: 1 | O12: 2 | P12: =IF(AND(N12>0,O12=0),"Yes","No") | Q12: 2 | R12: 0 | S12: 0 | T12: C++ | U12: 6.5 | V12: Submission 913185817 | W12: Open code | X12: 0 | Y12: 2023-03
A13: 12 | B13: 64 | C13: Minimum Path Sum | D13: Medium | E13: DP: Grid / 2D | F13: Min-cost path | G13: Dynamic Programming | H13: array, dynamic-programming, matrix | I13: Solved | J13: 44997.468 | K13: 44997.47 | L13: 44997.47 | M13: 2 | N13: 1 | O13: 1 | P13: =IF(AND(N13>0,O13=0),"Yes","No") | Q13: 1 | R13: 0 | S13: 0 | T13: C++ | U13: 5.9 | V13: Submission 913635348 | W13: Open code | X13: 1 | Y13: 2023-03
... A89: 88 | B89: 1136 | C89: Parallel Courses | D89: Medium | E89: Graph: Topological Sort | F89: Kahn by levels | G89: Graphs | H89: graph, topological-sort, directed-acyclic-graph | I89: Solved | J89: 45009.838 | K89: 45009.838 | L89: 45009.848 | M89: 2 | N89: 2 | O89: 0 | P89: =IF(AND(N89>0,O89=0),"Yes","No") | Q89: 0 | R89: 0 | S89: 0 | T89: C++ | U89: 5.1 | V89: Submission 921343418 | W89: Open code | X89: 3 | Y89: 2023-03
A90: 89 | B90: 1494 | C90: Parallel Courses II | D90: Hard | E90: DP: Bitmask | F90: Bitmask DP over courses | G90: Dynamic Programming | H90: dynamic-programming, bit-manipulation, graph, bitmask, directed-acyclic-graph | I90: Attempted | J90: 45009.905 | L90: 45009.905 | M90: 1 | N90: 0 | O90: 1 | P90: =IF(AND(N90>0,O90=0),"Yes","No") | Q90: 1 | R90: 0 | S90: 0 | T90: C++ | W90: Open code | X90: 1
A91: 90 | B91: 1105 | C91: Filling Bookcase Shelves | D91: Medium | E91: DP: Partition / Interval (MCM) | F91: Front partition DP | G91: Dynamic Programming | H91: array, dynamic-programming | I91: Solved | J91: 45010.026 | K91: 45010.031 | L91: 45010.04 | M91: 4 | N91: 1 | O91: 1 | P91: =IF(AND(N91>0,O91=0),"Yes","No") | Q91: 0 | R91: 1 | S91: 0 | T91: C++ | U91: 5 | V91: Submission 921478900 | W91: Open code | X91: 0 | Y91: 2023-03
A92: 91 | B92: 366 | C92: Find Leaves of Binary Tree | D92: Medium | E92: Binary Tree (DFS & Recursion) | F92: Group by height | G92: Trees | H92: tree, depth-first-search, binary-tree, dp-on-trees | I92: Solved | J92: 45010.051 | K92: 45010.051 | L92: 45010.051 | M92: 1 | N92: 1 | O92: 0 | P92: =IF(AND(N92>0,O92=0),"Yes","No") | Q92: 0 | R92: 0 | S92: 0 | T92: C++ | U92: 0 | V92: Submission 921490889 | W92: Open code | X92: 0 | Y92: 2023-03
A93: 92 | B93: 1202 | C93: Smallest String With Swaps | D93: Medium | E93: Graph: Union-Find | F93: Components + sort | G93: Graphs | H93: array, hash-table, string, depth-first-search, breadth-first-search, union-find, sorting | I93: Solved | J93: 45010.081 | K93: 45010.081 | L93: 45010.081 | M93: 1 | N93: 1 | O93: 0 | P93: =IF(AND(N93>0,O93=0),"Yes","No") | Q93: 0 | R93: 0 | S93: 0 | T93: C++ | U93: 5 | V93: Submission 921506988 | W93: Open code | X93: 2 | Y93: 2023-03
A94: 93 | B94: 2034 | C94: Stock Price Fluctuation | D94: Medium | E94: Design | F94: Map + lazy heaps | G94: Design | H94: hash-table, design, heap-priority-queue, data-stream, ordered-set | I94: Solved | J94: 45010.098 | K94: 45010.098 | L94: 45010.098 | M94: 1 | N94: 1 | O94: 0 | P94: =IF(AND(N94>0,O94=0),"Yes","No") | Q94: 0 | R94: 0 | S94: 0 | T94: C++ | U94: 5.1 | V94: Submission 921515192 | W94: Open code | X94: 0 | Y94: 2023-03
A95: 94 | B95: 22 | C95: Generate Parentheses | D95: Medium | E95: Backtracking | F95: Balanced generation | G95: Recursion & Backtracking | H95: string, dynamic-programming, backtracking, bracket-sequences | I95: Solved | J95: 45010.139 | K95: 45010.139 | L95: 45066.613 | M95: 5 | N95: 5 | O95: 0 | P95: =IF(AND(N95>0,O95=0),"Yes","No") | Q95: 0 | R95: 0 | S95: 0 | T95: C++ | U95: 66.5 | V95: Submission 953809671 | W95: Open code | X95: 0 | Y95: 2023-03
A96: 95 | B96: 3 | C96: Longest Substring Without Repeating Characters | D96: Medium | E96: Sliding Window | F96: Variable window, unique chars | G96: Arrays & Strings | H96: hash-table, string, sliding-window | I96: Solved | J96: 45010.507 | K96: 45010.507 | L96: 45248.254 | M96: 2 | N96: 2 | O96: 0 | P96: =IF(AND(N96>0,O96=0),"Yes","No") | Q96: 0 | R96: 0 | S96: 0 | T96: C++, Python3 | U96: 99.9 | V96: Submission 1101104428 | W96: Open code | X96: 8 | Y96: 2023-03
A97: 96 | B97: 33 | C97: Search in Rotated Sorted Array | D97: Medium | E97: Binary Search | F97: Rotated array | G97: Searching | H97: array, binary-search | I97: Solved | J97: 45010.54 | K97: 45010.54 | L97: 45738.624 | M97: 8 | N97: 7 | O97: 0 | P97: =IF(AND(N97>0,O97=0),"Yes","No") | Q97: 0 | R97: 0 | S97: 0 | T97: C++, Python3 | U97: 100 | V97: Submission 1138961252 | W97: Open code | X97: 10 | Y97: 2023-03
A98: 97 | B98: 210 | C98: Course Schedule II | D98: Medium | E98: Graph: Topological Sort | F98: Kahn order | G98: Graphs | H98: depth-first-search, breadth-first-search, graph, topological-sort | I98: Solved | J98: 45010.568 | K98: 45010.568 | L98: 45010.568 | M98: 1 | N98: 1 | O98: 0 | P98: =IF(AND(N98>0,O98=0),"Yes","No") | Q98: 0 | R98: 0 | S98: 0 | T98: C++ | U98: 5.1 | V98: Submission 921728668 | W98: Open code | X98: 1 | Y98: 2023-03
A99: 98 | B99: 328 | C99: Odd Even Linked List | D99: Medium | E99: Linked List | F99: Re-linking | G99: Linked List | H99: linked-list | I99: Solved | J99: 45010.604 | K99: 45010.604 | L99: 45010.604 | M99: 1 | N99: 1 | O99: 0 | P99: =IF(AND(N99>0,O99=0),"Yes","No") | Q99: 0 | R99: 0 | S99: 0 | T99: C++ | U99: 0.7 | V99: Submission 921750222 | W99: Open code | X99: 0 | Y99: 2023-03
A100: 99 | B100: 725 | C100: Split Linked List in Parts | D100: Medium | E100: Linked List | F100: Split by length | G100: Linked List | H100: linked-list | I100: Solved | J100: 45010.625 | K100: 45010.625 | L100: 45010.625 | M100: 2 | N100: 1 | O100: 1 | P100: =IF(AND(N100>0,O100=0),"Yes","No") | Q100: 1 | R100: 0 | S100: 0 | T100: C++ | U100: 0.1 | V100: Submission 921762544 | W100: Open code | X100: 0 | Y100: 2023-03
A101: 100 | B101: 61 | C101: Rotate List | D101: Medium | E101: Linked List | F101: Rotate by k | G101: Linked List | H101: linked-list, two-pointers | I101: Solved | J101: 45010.635 | K101: 45010.638 | L101: 45010.638 | M101: 4 | N101: 1 | O101: 3 | P101: =IF(AND(N101>0,O101=0),"Yes","No") | Q101: 0 | R101: 0 | S101: 3 | T101: C++ | U101: 0.7 | V101: Submission 921770509 | W101: Open code | X101: 1 | Y101: 2023-03
A102: 101 | B102: 148 | C102: Sort List | D102: Medium | E102: Linked List | F102: Merge sort on list | G102: Linked List | H102: linked-list, two-pointers, divide-and-conquer, sorting, merge-sort | I102: Solved | J102: 45010.651 | K102: 45010.651 | L102: 45010.651 | M102: 1 | N102: 1 | O102: 0 | P102: =IF(AND(N102>0,O102=0),"Yes","No") | Q102: 0 | R102: 0 | S102: 0 | T102: C++ | U102: 5.2 | V102: Submission 921778877 | W102: Open code | X102: 1 | Y102: 2023-03
... A146: 145 | B146: 353 | C146: Design Snake Game | D146: Medium | E146: Design | F146: Deque + set | G146: Design | H146: array, hash-table, design, queue, simulation | I146: Solved | J146: 45042.582 | K146: 45042.594 | L146: 45042.676 | M146: 3 | N146: 2 | O146: 1 | P146: =IF(AND(N146>0,O146=0),"Yes","No") | Q146: 1 | R146: 0 | S146: 0 | T146: C++ | U146: 25.9 | V146: Submission 940007168 | W146: Open code | X146: 0 | Y146: 2023-04
A147: 146 | B147: 381 | C147: Insert Delete GetRandom O(1) - Duplicates allowed | D147: Hard | E147: Design | F147: Array + index map | G147: Design | H147: array, hash-table, math, design, randomized | I147: Attempted | J147: 45042.693 | L147: 45042.698 | M147: 2 | N147: 0 | O147: 2 | P147: =IF(AND(N147>0,O147=0),"Yes","No") | Q147: 1 | R147: 1 | S147: 0 | T147: C++ | W147: Open code | X147: 4
A148: 147 | B148: 39 | C148: Combination Sum | D148: Medium | E148: Backtracking | F148: Combinations with reuse | G148: Recursion & Backtracking | H148: array, backtracking | I148: Solved | J148: 45044.426 | K148: 45044.426 | L148: 45588.505 | M148: 2 | N148: 2 | O148: 0 | P148: =IF(AND(N148>0,O148=0),"Yes","No") | Q148: 0 | R148: 0 | S148: 0 | T148: C++ | U148: 100 | V148: Submission 1431182072 | W148: Open code | X148: 2 | Y148: 2023-04
A149: 148 | B149: 40 | C149: Combination Sum II | D149: Medium | E149: Backtracking | F149: Combinations with duplicates | G149: Recursion & Backtracking | H149: array, backtracking | I149: Solved | J149: 45044.439 | K149: 45044.452 | L149: 45588.512 | M149: 4 | N149: 2 | O149: 1 | P149: =IF(AND(N149>0,O149=0),"Yes","No") | Q149: 0 | R149: 1 | S149: 0 | T149: C++ | U149: 100 | V149: Submission 1431190430 | W149: Open code | X149: 0 | Y149: 2023-04
A150: 149 | B150: 51 | C150: N-Queens | D150: Hard | E150: Backtracking | F150: Constraint placement | G150: Recursion & Backtracking | H150: array, backtracking, algorithm-x | I150: Solved | J150: 45044.521 | K150: 45044.521 | L150: 45044.528 | M150: 2 | N150: 2 | O150: 0 | P150: =IF(AND(N150>0,O150=0),"Yes","No") | Q150: 0 | R150: 0 | S150: 0 | T150: C++ | U150: 13.1 | V150: Submission 940980279 | W150: Open code | X150: 3 | Y150: 2023-04
A151: 150 | B151: 37 | C151: Sudoku Solver | D151: Hard | E151: Backtracking | F151: Constraint search | G151: Recursion & Backtracking | H151: array, hash-table, backtracking, matrix, algorithm-x, dancing-links | I151: Solved | J151: 45044.554 | K151: 45044.554 | L151: 45044.554 | M151: 1 | N151: 1 | O151: 0 | P151: =IF(AND(N151>0,O151=0),"Yes","No") | Q151: 0 | R151: 0 | S151: 0 | T151: C++ | U151: 95.7 | V151: Submission 940993417 | W151: Open code | X151: 0 | Y151: 2023-04
A152: 151 | B152: 131 | C152: Palindrome Partitioning | D152: Medium | E152: Backtracking | F152: Partition backtracking | G152: Recursion & Backtracking | H152: string, dynamic-programming, backtracking | I152: Solved | J152: 45044.629 | K152: 45044.629 | L152: 45044.629 | M152: 1 | N152: 1 | O152: 0 | P152: =IF(AND(N152>0,O152=0),"Yes","No") | Q152: 0 | R152: 0 | S152: 0 | T152: C++ | U152: 12.4 | V152: Submission 941029531 | W152: Open code | X152: 0 | Y152: 2023-04
A153: 152 | B153: 60 | C153: Permutation Sequence | D153: Hard | E153: Math & Bit Manipulation | F153: Factorial number system | G153: Arrays & Strings | H153: math, recursion | I153: Solved | J153: 45044.649 | K153: 45044.663 | L153: 45044.663 | M153: 4 | N153: 1 | O153: 3 | P153: =IF(AND(N153>0,O153=0),"Yes","No") | Q153: 0 | R153: 2 | S153: 1 | T153: C++ | U153: 100 | V153: Submission 941045258 | W153: Open code | X153: 0 | Y153: 2023-04
A154: 153 | B154: 875 | C154: Koko Eating Bananas | D154: Medium | E154: Binary Search on Answer | F154: Minimise speed | G154: Searching | H154: array, binary-search | I154: Solved | J154: 45044.791 | K154: 45044.791 | L154: 45738.9 | M154: 12 | N154: 6 | O154: 0 | P154: =IF(AND(N154>0,O154=0),"Yes","No") | Q154: 0 | R154: 0 | S154: 0 | T154: C++, Python3 | U154: 52.4 | V154: Submission 1582420275 | W154: Open code | X154: 0 | Y154: 2023-04
A155: 154 | B155: 994 | C155: Rotting Oranges | D155: Medium | E155: Graph: Grid BFS/DFS | F155: Multi-source BFS | G155: Graphs | H155: array, breadth-first-search, matrix | I155: Solved | J155: 45045.38 | K155: 45045.38 | L155: 45778.43 | M155: 2 | N155: 2 | O155: 0 | P155: =IF(AND(N155>0,O155=0),"Yes","No") | Q155: 0 | R155: 0 | S155: 0 | T155: C++ | U155: 40.7 | V155: Submission 1622478711 | W155: Open code | X155: 0 | Y155: 2023-04
A156: 155 | B156: 542 | C156: 01 Matrix | D156: Medium | E156: Graph: Grid BFS/DFS | F156: Multi-source BFS | G156: Graphs | H156: array, dynamic-programming, breadth-first-search, matrix | I156: Solved | J156: 45045.406 | K156: 45045.406 | L156: 45045.407 | M156: 2 | N156: 2 | O156: 0 | P156: =IF(AND(N156>0,O156=0),"Yes","No") | Q156: 0 | R156: 0 | S156: 0 | T156: C++ | U156: 5 | V156: Submission 941376684 | W156: Open code | X156: 0 | Y156: 2023-04
A157: 156 | B157: 1020 | C157: Number of Enclaves | D157: Medium | E157: Graph: Grid BFS/DFS | F157: Border flood fill | G157: Graphs | H157: array, depth-first-search, breadth-first-search, union-find, matrix | I157: Solved | J157: 45045.441 | K157: 45045.441 | L157: 45045.441 | M157: 1 | N157: 1 | O157: 0 | P157: =IF(AND(N157>0,O157=0),"Yes","No") | Q157: 0 | R157: 0 | S157: 0 | T157: C++ | U157: 5 | V157: Submission 941390538 | W157: Open code | X157: 0 | Y157: 2023-04
A158: 157 | B158: 694 | C158: Number of Distinct Islands | D158: Medium | E158: Graph: Grid BFS/DFS | F158: Shape signature | G158: Graphs | H158: array, hash-table, depth-first-search, breadth-first-search, union-find, sorting, matrix, hash-function | I158: Solved | J158: 45045.501 | K158: 45045.501 | L158: 45217.597 | M158: 2 | N158: 2 | O158: 0 | P158: =IF(AND(N158>0,O158=0),"Yes","No") | Q158: 0 | R158: 0 | S158: 0 | T158: C++ | U158: 11.7 | V158: Submission 1078223567 | W158: Open code | X158: 1 | Y158: 2023-04
...

Sheet Other Problems
A1: # | B1: LC # | C1: Problem | D1: Difficulty | E1: Pattern | F1: Sub-pattern | G1: Topic group | H1: LeetCode tags | I1: LC status | J1: First attempt | K1: First accepted | L1: Last submission | M1: Submissions | N1: Accepted | O1: Failed before first AC | P1: First-try AC? | Q1: Wrong Answer (before AC) | R1: TLE (before AC) | S1: Other errors (before AC) | T1: Languages | U1: Best runtime beats % | V1: Latest accepted submission | W1: Code & attempts file | X1: Pre-Mar-2023 subs (excluded) | Y1: First AC month | Z1: Mine? (Y/N)
A2: 1 | B2: 1480 | C2: Running Sum of 1d Array | D2: Easy | E2: Prefix Sum & Difference Array | F2: Running sum | G2: Arrays & Strings | H2: array, prefix-sum | I2: Ac | J2: 44991.879 | K2: 44991.879 | L2: 44991.879 | M2: 1 | N2: 1 | O2: 0 | P2: =IF(AND(N2>0,O2=0),"Yes","No") | Q2: 0 | R2: 0 | S2: 0 | T2: C++ | U2: 100 | V2: Submission 910238803 | W2: Open code | X2: 0 | Y2: 2023-03
A3: 2 | B3: 724 | C3: Find Pivot Index | D3: Easy | E3: Prefix Sum & Difference Array | F3: Prefix sum | G3: Arrays & Strings | H3: array, prefix-sum | I3: Ac | J3: 44991.886 | K3: 44991.886 | L3: 45170.968 | M3: 2 | N3: 2 | O3: 0 | P3: =IF(AND(N3>0,O3=0),"Yes","No") | Q3: 0 | R3: 0 | S3: 0 | T3: C++ | U3: 9.4 | V3: Submission 1037856937 | W3: Open code | X3: 0 | Y3: 2023-03
A4: 3 | B4: 314 | C4: Binary Tree Vertical Order Traversal | D4: Medium | E4: Binary Tree (BFS / Level Order) | F4: Column BFS | G4: Trees | H4: hash-table, tree, depth-first-search, breadth-first-search, sorting, binary-tree | I4: Ac | J4: 45119.931 | K4: 45119.931 | L4: 45264.395 | M4: 4 | N4: 2 | O4: 1 | P4: =IF(AND(N4>0,O4=0),"Yes","No") | Q4: 1 | R4: 0 | S4: 0 | T4: Python3 | U4: 0.1 | V4: Submission 1111892126 | W4: Open code | X4: 0 | Y4: 2023-07
A5: 4 | B5: 1768 | C5: Merge Strings Alternately | D5: Easy | E5: Two Pointers | F5: Interleave | G5: Arrays & Strings | H5: two-pointers, string | J5: 45155.995 | K5: 45155.995 | L5: 45155.995 | M5: 1 | N5: 1 | O5: 0 | P5: =IF(AND(N5>0,O5=0),"Yes","No") | Q5: 0 | R5: 0 | S5: 0 | T5: C++ | U5: 30.1 | V5: Submission 1024218483 | W5: Open code | X5: 0 | Y5: 2023-08
A6: 5 | B6: 1071 | C6: Greatest Common Divisor of Strings | D6: Easy | E6: Math & Bit Manipulation | F6: GCD | G6: Arrays & Strings | H6: math, string, euclidean-algorithm, greatest-common-divisor | J6: 45156.032 | K6: 45156.033 | L6: 45156.033 | M6: 2 | N6: 1 | O6: 1 | P6: =IF(AND(N6>0,O6=0),"Yes","No") | Q6: 1 | R6: 0 | S6: 0 | T6: C++ | U6: 5.1 | V6: Submission 1024263824 | W6: Open code | X6: 0 | Y6: 2023-08
A7: 6 | B7: 1431 | C7: Kids With the Greatest Number of Candies | D7: Easy | E7: Arrays, Hashing & Sorting | F7: Max scan | G7: Arrays & Strings | H7: array | J7: 45156.915 | K7: 45156.915 | L7: 45156.915 | M7: 1 | N7: 1 | O7: 0 | P7: =IF(AND(N7>0,O7=0),"Yes","No") | Q7: 0 | R7: 0 | S7: 0 | T7: C++ | U7: 100 | V7: Submission 1025007443 | W7: Open code | X7: 0 | Y7: 2023-08
A8: 7 | B8: 605 | C8: Can Place Flowers | D8: Easy | E8: Greedy | F8: Greedy placement | G8: Greedy | H8: array, greedy | J8: 45156.952 | K8: 45156.994 | L8: 45156.994 | M8: 3 | N8: 1 | O8: 2 | P8: =IF(AND(N8>0,O8=0),"Yes","No") | Q8: 1 | R8: 1 | S8: 0 | T8: C++ | U8: 2.9 | V8: Submission 1025106754 | W8: Open code | X8: 0 | Y8: 2023-08
A9: 8 | B9: 345 | C9: Reverse Vowels of a String | D9: Easy | E9: Two Pointers | F9: Opposite ends | G9: Arrays & Strings | H9: two-pointers, string | J9: 45157.01 | K9: 45157.011 | L9: 45157.011 | M9: 2 | N9: 1 | O9: 1 | P9: =IF(AND(N9>0,O9=0),"Yes","No") | Q9: 1 | R9: 0 | S9: 0 | T9: C++ | U9: 32.3 | V9: Submission 1025126413 | W9: Open code | X9: 0 | Y9: 2023-08
A10: 9 | B10: 151 | C10: Reverse Words in a String | D10: Medium | E10: Two Pointers | F10: Reverse words | G10: Arrays & Strings | H10: two-pointers, string | J10: 45161.815 | K10: 45161.815 | L10: 45161.815 | M10: 1 | N10: 1 | O10: 0 | P10: =IF(AND(N10>0,O10=0),"Yes","No") | Q10: 0 | R10: 0 | S10: 0 | T10: C++ | U10: 13.4 | V10: Submission 1029596542 | W10: Open code | X10: 0 | Y10: 2023-08
A11: 10 | B11: 238 | C11: Product of Array Except Self | D11: Medium | E11: Prefix Sum & Difference Array | F11: Prefix/suffix product | G11: Arrays & Strings | H11: array, prefix-sum | I11: Ac | J11: 45161.831 | K11: 45161.831 | L11: 45161.835 | M11: 2 | N11: 2 | O11: 0 | P11: =IF(AND(N11>0,O11=0),"Yes","No") | Q11: 0 | R11: 0 | S11: 0 | T11: C++ | U11: 6.2 | V11: Submission 1029620534 | W11: Open code | X11: 0 | Y11: 2023-08
A12: 11 | B12: 334 | C12: Increasing Triplet Subsequence | D12: Medium | E12: Greedy | F12: Two running minimums | G12: Greedy | H12: array, greedy, longest-increasing-subsequence | J12: 45161.852 | K12: 45161.855 | L12: 45161.862 | M12: 4 | N12: 2 | O12: 1 | P12: =IF(AND(N12>0,O12=0),"Yes","No") | Q12: 1 | R12: 0 | S12: 0 | T12: C++ | U12: 5 | V12: Submission 1029652848 | W12: Open code | X12: 0 | Y12: 2023-08
A13: 12 | B13: 443 | C13: String Compression | D13: Medium | E13: Two Pointers | F13: Read/write pointers | G13: Arrays & Strings | H13: two-pointers, string | J13: 45162.006 | K13: 45162.027 | L13: 45162.032 | M13: 7 | N13: 2 | O13: 5 | P13: =IF(AND(N13>0,O13=0),"Yes","No") | Q13: 5 | R13: 0 | S13: 0 | T13: C++ | U13: 2.3 | V13: Submission 1029879136 | W13: Open code | X13: 0 | Y13: 2023-08
A14: 13 | B14: 283 | C14: Move Zeroes | D14: Easy | E14: Two Pointers | F14: Read/write pointers | G14: Arrays & Strings | H14: array, two-pointers | I14: Ac | J14: 45162.938 | K14: 45162.938 | L14: 45265.109 | M14: 13 | N14: 10 | O14: 0 | P14: =IF(AND(N14>0,O14=0),"Yes","No") | Q14: 0 | R14: 0 | S14: 0 | T14: C++, Python, Python3 | U14: 10.2 | V14: Submission 1112443699 | W14: Open code | X14: 0 | Y14: 2023-08
A15: 14 | B15: 392 | C15: Is Subsequence | D15: Easy | E15: Two Pointers | F15: Subsequence scan | G15: Arrays & Strings | H15: two-pointers, string, dynamic-programming | I15: Ac | J15: 45162.945 | K15: 45162.946 | L15: 45162.946 | M15: 2 | N15: 1 | O15: 1 | P15: =IF(AND(N15>0,O15=0),"Yes","No") | Q15: 1 | R15: 0 | S15: 0 | T15: C++ | U15: 4.7 | V15: Submission 1030693648 | W15: Open code | X15: 0 | Y15: 2023-08
A16: 15 | B16: 11 | C16: Container With Most Water | D16: Medium | E16: Two Pointers | F16: Opposite ends | G16: Arrays & Strings | H16: array, two-pointers, greedy | I16: Ac | J16: 45162.977 | K16: 45162.977 | L16: 45162.977 | M16: 1 | N16: 1 | O16: 0 | P16: =IF(AND(N16>0,O16=0),"Yes","No") | Q16: 0 | R16: 0 | S16: 0 | T16: C++ | U16: 6.1 | V16: Submission 1030734523 | W16: Open code | X16: 0 | Y16: 2023-08
A17: 16 | B17: 1679 | C17: Max Number of K-Sum Pairs | D17: Medium | E17: Two Pointers | F17: Sort + two pointers | G17: Arrays & Strings | H17: array, hash-table, two-pointers, sorting | I17: Ac | J17: 45162.989 | K17: 45162.991 | L17: 45162.991 | M17: 2 | N17: 1 | O17: 1 | P17: =IF(AND(N17>0,O17=0),"Yes","No") | Q17: 1 | R17: 0 | S17: 0 | T17: C++ | U17: 5.1 | V17: Submission 1030753639 | W17: Open code | X17: 0 | Y17: 2023-08
A18: 17 | B18: 643 | C18: Maximum Average Subarray I | D18: Easy | E18: Sliding Window | F18: Fixed window | G18: Arrays & Strings | H18: array, sliding-window | I18: Ac | J18: 45163.006 | K18: 45163.006 | L18: 45248.27 | M18: 2 | N18: 2 | O18: 0 | P18: =IF(AND(N18>0,O18=0),"Yes","No") | Q18: 0 | R18: 0 | S18: 0 | T18: C++, Python3 | U18: 7.6 | V18: Submission 1101111135 | W18: Open code | X18: 0 | Y18: 2023-08
A19: 18 | B19: 1456 | C19: Maximum Number of Vowels in a Substring of Given Length | D19: Medium | E19: Sliding Window | F19: Fixed window | G19: Arrays & Strings | H19: string, sliding-window | J19: 45163.942 | K19: 45163.942 | L19: 45163.947 | M19: 6 | N19: 6 | O19: 0 | P19: =IF(AND(N19>0,O19=0),"Yes","No") | Q19: 0 | R19: 0 | S19: 0 | T19: C++ | U19: 6.2 | V19: Submission 1031598078 | W19: Open code | X19: 0 | Y19: 2023-08
A20: 19 | B20: 1004 | C20: Max Consecutive Ones III | D20: Medium | E20: Sliding Window | F20: At most k zeros | G20: Arrays & Strings | H20: array, binary-search, sliding-window, prefix-sum | I20: Ac | J20: 45163.983 | K20: 45163.983 | L20: 45318.931 | M20: 4 | N20: 4 | O20: 0 | P20: =IF(AND(N20>0,O20=0),"Yes","No") | Q20: 0 | R20: 0 | S20: 0 | T20: C++, Python3 | U20: 5.8 | V20: Submission 1158417154 | W20: Open code | X20: 0 | Y20: 2023-08
A21: 20 | B21: 1493 | C21: Longest Subarray of 1's After Deleting One Element | D21: Medium | E21: Sliding Window | F21: At most 1 zero | G21: Arrays & Strings | H21: array, dynamic-programming, sliding-window | J21: 45170.874 | K21: 45170.874 | L21: 45170.874 | M21: 1 | N21: 1 | O21: 0 | P21: =IF(AND(N21>0,O21=0),"Yes","No") | Q21: 0 | R21: 0 | S21: 0 | T21: C++ | U21: 6.2 | V21: Submission 1037751435 | W21: Open code | X21: 0 | Y21: 2023-09
A22: 21 | B22: 1732 | C22: Find the Highest Altitude | D22: Easy | E22: Prefix Sum & Difference Array | F22: Running sum | G22: Arrays & Strings | H22: array, prefix-sum | J22: 45170.964 | K22: 45170.964 | L22: 45170.964 | M22: 1 | N22: 1 | O22: 0 | P22: =IF(AND(N22>0,O22=0),"Yes","No") | Q22: 0 | R22: 0 | S22: 0 | T22: C++ | U22: 100 | V22: Submission 1037851819 | W22: Open code | X22: 0 | Y22: 2023-09
A23: 22 | B23: 2215 | C23: Find the Difference of Two Arrays | D23: Easy | E23: Arrays, Hashing & Sorting | F23: Sets | G23: Arrays & Strings | H23: array, hash-table | J23: 45177.701 | K23: 45177.701 | L23: 45177.701 | M23: 1 | N23: 1 | O23: 0 | P23: =IF(AND(N23>0,O23=0),"Yes","No") | Q23: 0 | R23: 0 | S23: 0 | T23: C++ | U23: 5 | V23: Submission 1043842772 | W23: Open code | X23: 0 | Y23: 2023-09
A24: 23 | B24: 1207 | C24: Unique Number of Occurrences | D24: Easy | E24: Arrays, Hashing & Sorting | F24: Counting | G24: Arrays & Strings | H24: array, hash-table | J24: 45177.962 | K24: 45177.962 | L24: 45177.962 | M24: 1 | N24: 1 | O24: 0 | P24: =IF(AND(N24>0,O24=0),"Yes","No") | Q24: 0 | R24: 0 | S24: 0 | T24: C++ | U24: 100 | V24: Submission 1044102868 | W24: Open code | X24: 0 | Y24: 2023-09
A25: 24 | B25: 2352 | C25: Equal Row and Column Pairs | D25: Medium | E25: Arrays, Hashing & Sorting | F25: Row hash count | G25: Arrays & Strings | H25: array, hash-table, matrix, simulation | J25: 45178.014 | K25: 45178.014 | L25: 45178.014 | M25: 1 | N25: 1 | O25: 0 | P25: =IF(AND(N25>0,O25=0),"Yes","No") | Q25: 0 | R25: 0 | S25: 0 | T25: C++ | U25: 34.8 | V25: Submission 1044163612 | W25: Open code | X25: 0 | Y25: 2023-09
A26: 25 | B26: 2390 | C26: Removing Stars From a String | D26: Medium | E26: Stack | F26: Stack | G26: Stacks & Queues | H26: string, stack, simulation | J26: 45181.837 | K26: 45181.844 | L26: 45181.844 | M26: 2 | N26: 1 | O26: 1 | P26: =IF(AND(N26>0,O26=0),"Yes","No") | Q26: 0 | R26: 0 | S26: 1 | T26: C++ | U26: 0 | V26: Submission 1047537156 | W26: Open code | X26: 0 | Y26: 2023-09
A27: 26 | B27: 735 | C27: Asteroid Collision | D27: Medium | E27: Stack | F27: Collision stack | G27: Stacks & Queues | H27: array, stack, simulation | J27: 45181.855 | K27: 45181.865 | L27: 45181.871 | M27: 3 | N27: 2 | O27: 1 | P27: =IF(AND(N27>0,O27=0),"Yes","No") | Q27: 0 | R27: 0 | S27: 1 | T27: C++ | U27: 5.5 | V27: Submission 1047569035 | W27: Open code | X27: 0 | Y27: 2023-09
A28: 27 | B28: 394 | C28: Decode String | D28: Medium | E28: Stack | F28: Nested decode stack | G28: Stacks & Queues | H28: string, stack, recursion | J28: 45182.008 | K28: 45182.009 | L28: 45182.009 | M28: 2 | N28: 1 | O28: 1 | P28: =IF(AND(N28>0,O28=0),"Yes","No") | Q28: 1 | R28: 0 | S28: 0 | T28: C++ | U28: 0.8 | V28: Submission 1047748694 | W28: Open code | X28: 0 | Y28: 2023-09
A29: 28 | B29: 933 | C29: Number of Recent Calls | D29: Easy | E29: Design | F29: Queue | G29: Design | H29: design, queue, data-stream | J29: 45182.026 | K29: 45182.026 | L29: 45182.026 | M29: 1 | N29: 1 | O29: 0 | P29: =IF(AND(N29>0,O29=0),"Yes","No") | Q29: 0 | R29: 0 | S29: 0 | T29: C++ | U29: 5.7 | V29: Submission 1047767716 | W29: Open code | X29: 0 | Y29: 2023-09
A30: 29 | B30: 408 | C30: Valid Word Abbreviation | D30: Easy | E30: Two Pointers | F30: Two-pointer parse | G30: Arrays & Strings | H30: two-pointers, string | I30: Ac | J30: 45239.167 | K30: 45239.167 | L30: 45303.911 | M30: 2 | N30: 2 | O30: 0 | P30: =IF(AND(N30>0,O30=0),"Yes","No") | Q30: 0 | R30: 0 | S30: 0 | T30: Python3 | U30: 0.4 | V30: Submission 1144355158 | W30: Open code | X30: 0 | Y30: 2023-11
A31: 30 | B31: 339 | C31: Nested List Weight Sum | D31: Medium | E31: Binary Tree (DFS & Recursion) | F31: Recursive depth sum | G31: Trees | H31: depth-first-search, breadth-first-search | I31: Ac | J31: 45240.23 | K31: 45261.133 | L31: 45264.482 | M31: 5 | N31: 2 | O31: 1 | P31: =IF(AND(N31>0,O31=0),"Yes","No") | Q31: 0 | R31: 0 | S31: 1 | T31: Python3 | U31: 0 | V31: Submission 1111957079 | W31: Open code | X31: 0 | Y31: 2023-12
A32: 31 | B32: 827 | C32: Making A Large Island | D32: Hard | E32: Graph: Grid BFS/DFS | F32: Label islands + merge | G32: Graphs | H32: array, depth-first-search, breadth-first-search, union-find, matrix | I32: Ac | J32: 45242.989 | K32: 45243.026 | L32: 45328.3 | M32: 28 | N32: 5 | O32: 3 | P32: =IF(AND(N32>0,O32=0),"Yes","No") | Q32: 0 | R32: 1 | S32: 2 | T32: Python3 | U32: 5 | V32: Submission 1167335012 | W32: Open code | X32: 0 | Y32: 2023-11
A33: 32 | B33: 921 | C33: Minimum Add to Make Parentheses Valid | D33: Medium | E33: Greedy | F33: Balance counter | G33: Greedy | H33: string, stack, greedy, bracket-sequences | I33: Ac | J33: 45243.039 | K33: 45243.039 | L33: 45265.03 | M33: 4 | N33: 4 | O33: 0 | P33: =IF(AND(N33>0,O33=0),"Yes","No") | Q33: 0 | R33: 0 | S33: 0 | T33: Python3 | U33: 0.6 | V33: Submission 1112386888 | W33: Open code | X33: 0 | Y33: 2023-11
A34: 33 | B34: 766 | C34: Toeplitz Matrix | D34: Easy | E34: Strings & Simulation | F34: Matrix scan | G34: Arrays & Strings | H34: array, matrix | I34: Ac | J34: 45244.89 | K34: 45244.89 | L34: 45265.013 | M34: 2 | N34: 2 | O34: 0 | P34: =IF(AND(N34>0,O34=0),"Yes","No") | Q34: 0 | R34: 0 | S34: 0 | T34: Python3 | U34: 4.7 | V34: Submission 1112372456 | W34: Open code | X34: 0 | Y34: 2023-11
A35: 34 | B35: 199 | C35: Binary Tree Right Side View | D35: Medium | E35: Binary Tree (BFS / Level Order) | F35: Last node per level | G35: Trees | H35: tree, depth-first-search, breadth-first-search, binary-tree | I35: Ac | J35: 45245.893 | K35: 45245.893 | L35: 45313.073 | M35: 3 | N35: 3 | O35: 0 | P35: =IF(AND(N35>0,O35=0),"Yes","No") | Q35: 0 | R35: 0 | S35: 0 | T35: Python3 | U35: 0.5 | V35: Submission 1152935407 | W35: Open code | X35: 0 | Y35: 2023-11
A36: 35 | B36: 88 | C36: Merge Sorted Array | D36: Easy | E36: Two Pointers | F36: Merge from the end | G36: Arrays & Strings | H36: array, two-pointers, sorting | I36: Ac | J36: 45246.027 | K36: 45246.027 | L36: 45265.19 | M36: 3 | N36: 3 | O36: 0 | P36: =IF(AND(N36>0,O36=0),"Yes","No") | Q36: 0 | R36: 0 | S36: 0 | T36: Python, Python3 | U36: 3.1 | V36: Submission 1112489517 | W36: Open code | X36: 0 | Y36: 2023-11
A37: 36 | B37: 125 | C37: Valid Palindrome | D37: Easy | E37: Two Pointers | F37: Opposite ends | G37: Arrays & Strings | H37: two-pointers, string | I37: Ac | J37: 45246.198 | K37: 45246.198 | L37: 45326.415 | M37: 3 | N37: 3 | O37: 0 | P37: =IF(AND(N37>0,O37=0),"Yes","No") | Q37: 0 | R37: 0 | S37: 0 | T37: Python, Python3 | U37: 36.1 | V37: Submission 1165501847 | W37: Open code | X37: 0 | Y37: 2023-11
A38: 37 | B38: 670 | C38: Maximum Swap | D38: Medium | E38: Greedy | F38: Last occurrence | G38: Greedy | H38: math, greedy | I38: Ac | J38: 45246.256 | K38: 45253.15 | L38: 45325.116 | M38: 8 | N38: 3 | O38: 3 | P38: =IF(AND(N38>0,O38=0),"Yes","No") | Q38: 3 | R38: 0 | S38: 0 | T38: Python, Python3 | U38: 0 | V38: Submission 1164268995 | W38: Open code | X38: 0 | Y38: 2023-11
A39: 38 | B39: 986 | C39: Interval List Intersections | D39: Medium | E39: Intervals & Sweep Line | F39: Two-pointer intersection | G39: Heaps & Intervals | H39: array, two-pointers, sweep-line | I39: Ac | J39: 45246.853 | K39: 45246.853 | L39: 45332.095 | M39: 3 | N39: 3 | O39: 0 | P39: =IF(AND(N39>0,O39=0),"Yes","No") | Q39: 0 | R39: 0 | S39: 0 | T39: Python, Python3 | U39: 6.1 | V39: Submission 1170940559 | W39: Open code | X39: 0 | Y39: 2023-11
A40: 39 | B40: 296 | C40: Best Meeting Point | D40: Hard | E40: Math & Bit Manipulation | F40: Median | G40: Arrays & Strings | H40: array, math, sorting, matrix | I40: Ac | J40: 45247.051 | K40: 45247.06 | L40: 45327.302 | M40: 5 | N40: 2 | O40: 1 | P40: =IF(AND(N40>0,O40=0),"Yes","No") | Q40: 0 | R40: 1 | S40: 0 | T40: Python, Python3 | U40: 18.2 | V40: Submission 1112468782 | W40: Open code | X40: 0 | Y40: 2023-11
...

Sheet Submissions
A1: Submitted (IST) | B1: Month | C1: LC # | D1: Problem | E1: Difficulty | F1: Pattern | G1: Status | H1: Language | I1: Runtime | J1: Memory | K1: Runtime beats % | L1: Tests passed | M1: Submission | N1: In your list?
A2: 44991.879 | B2: 2023-03 | C2: 1480 | D2: Running Sum of 1d Array | E2: Easy | F2: Prefix Sum & Difference Array | G2: Accepted | H2: C++ | I2: 0 ms | J2: 8.6 MB | K2: 100 | L2: 53/53 | M2: Submission 910238803 | N2: No
A3: 44991.886 | B3: 2023-03 | C3: 724 | D3: Find Pivot Index | E3: Easy | F3: Prefix Sum & Difference Array | G3: Accepted | H3: C++ | I3: 31 ms | J3: 32.3 MB | K3: 9.4 | L3: 746/746 | M3: Submission 910244350 | N3: No
A4: 44991.912 | B4: 2023-03 | C4: 1 | D4: Two Sum | E4: Easy | F4: Arrays, Hashing & Sorting | G4: Accepted | H4: C++ | I4: 9 ms | J4: 11.3 MB | K4: 40.6 | L4: 57/57 | M4: Submission 910266383 | N4: Yes
A5: 44991.914 | B5: 2023-03 | C5: 1 | D5: Two Sum | E5: Easy | F5: Arrays, Hashing & Sorting | G5: Accepted | H5: C++ | I5: 14 ms | J5: 11.1 MB | K5: 39.3 | L5: 57/57 | M5: Submission 910268202 | N5: Yes
A6: 44991.939 | B6: 2023-03 | C6: 13 | D6: Roman to Integer | E6: Easy | F6: Strings & Simulation | G6: Accepted | H6: C++ | I6: 17 ms | J6: 8.6 MB | K6: 5.1 | L6: 3999/3999 | M6: Submission 910290507 | N6: Yes
A7: 44991.944 | B7: 2023-03 | C7: 14 | D7: Longest Common Prefix | E7: Easy | F7: Strings & Simulation | G7: Wrong Answer | H7: C++ | I7: N/A | J7: N/A | L7: 110/124 | M7: Submission 910295360 | N7: Yes
A8: 44991.945 | B8: 2023-03 | C8: 14 | D8: Longest Common Prefix | E8: Easy | F8: Strings & Simulation | G8: Accepted | H8: C++ | I8: 0 ms | J8: 9.2 MB | K8: 100 | L8: 124/124 | M8: Submission 910296028 | N8: Yes
A9: 44991.954 | B9: 2023-03 | C9: 20 | D9: Valid Parentheses | E9: Easy | F9: Stack | G9: Wrong Answer | H9: C++ | I9: N/A | J9: N/A | L9: 5/92 | M9: Submission 910304068 | N9: Yes
A10: 44991.954 | B10: 2023-03 | C10: 20 | D10: Valid Parentheses | E10: Easy | F10: Stack | G10: Runtime Error | H10: C++ | I10: N/A | J10: N/A | L10: 6/92 | M10: Submission 910304549 | N10: Yes
A11: 44991.958 | B11: 2023-03 | C11: 20 | D11: Valid Parentheses | E11: Easy | F11: Stack | G11: Accepted | H11: C++ | I11: 5 ms | J11: 6.1 MB | K11: 0.9 | L11: 92/92 | M11: Submission 910307496 | N11: Yes
A12: 44991.99 | B12: 2023-03 | C12: 359 | D12: Logger Rate Limiter | E12: Easy | F12: Design | G12: Accepted | H12: C++ | I12: 92 ms | J12: 36.8 MB | K12: 5.2 | L12: 20/20 | M12: Submission 910337699 | N12: Yes
A13: 44991.996 | B13: 2023-03 | C13: 359 | D13: Logger Rate Limiter | E13: Easy | F13: Design | G13: Accepted | H13: C++ | I13: 70 ms | J13: 32.6 MB | K13: 5.2 | L13: 20/20 | M13: Submission 910342011 | N13: Yes
A14: 44992.004 | B14: 2023-03 | C14: 704 | D14: Binary Search | E14: Easy | F14: Binary Search | G14: Accepted | H14: C++ | I14: 47 ms | J14: 27.6 MB | K14: 0.1 | L14: 47/47 | M14: Submission 910349125 | N14: Yes
A15: 44992.022 | B15: 2023-03 | C15: 704 | D15: Binary Search | E15: Easy | F15: Binary Search | G15: Accepted | H15: C++ | I15: 43 ms | J15: 27.4 MB | K15: 0.1 | L15: 47/47 | M15: Submission 910363447 | N15: Yes
A16: 44992.026 | B16: 2023-03 | C16: 938 | D16: Range Sum of BST | E16: Easy | F16: Binary Search Tree | G16: Accepted | H16: C++ | I16: 135 ms | J16: 64.6 MB | K16: 3 | L16: 41/41 | M16: Submission 910366212 | N16: Yes
A17: 44992.026 | B17: 2023-03 | C17: 1 | D17: Two Sum | E17: Easy | F17: Arrays, Hashing & Sorting | G17: Accepted | H17: C++ | I17: 18 ms | J17: 11.2 MB | K17: 39.2 | L17: 57/57 | M17: Submission 910366686 | N17: Yes
A18: 44992.027 | B18: 2023-03 | C18: 13 | D18: Roman to Integer | E18: Easy | F18: Strings & Simulation | G18: Accepted | H18: C++ | I18: 11 ms | J18: 8.7 MB | K18: 26.4 | L18: 3999/3999 | M18: Submission 910366895 | N18: Yes
A19: 44992.027 | B19: 2023-03 | C19: 14 | D19: Longest Common Prefix | E19: Easy | F19: Strings & Simulation | G19: Accepted | H19: C++ | I19: 4 ms | J19: 9.2 MB | K19: 5.5 | L19: 124/124 | M19: Submission 910366984 | N19: Yes
A20: 44992.027 | B20: 2023-03 | C20: 20 | D20: Valid Parentheses | E20: Easy | F20: Stack | G20: Accepted | H20: C++ | I20: 4 ms | J20: 6.4 MB | K20: 1.3 | L20: 92/92 | M20: Submission 910367099 | N20: Yes
A21: 44992.027 | B21: 2023-03 | C21: 359 | D21: Logger Rate Limiter | E21: Easy | F21: Design | G21: Accepted | H21: C++ | I21: 76 ms | J21: 32.6 MB | K21: 5.2 | L21: 20/20 | M21: Submission 910367286 | N21: Yes
A22: 44992.035 | B22: 2023-03 | C22: 938 | D22: Range Sum of BST | E22: Easy | F22: Binary Search Tree | G22: Accepted | H22: C++ | I22: 152 ms | J22: 64.6 MB | K22: 3 | L22: 41/41 | M22: Submission 910373064 | N22: Yes
... A25: 44992.071 | B25: 2023-03 | C25: 56 | D25: Merge Intervals | E25: Medium | F25: Intervals & Sweep Line | G25: Accepted | H25: C++ | I25: 43 ms | J25: 20.1 MB | K25: 5.1 | L25: 170/170 | M25: Submission 910397138 | N25: Yes
A26: 44996.411 | B26: 2023-03 | C26: 70 | D26: Climbing Stairs | E26: Easy | F26: DP: 1D / Linear | G26: Wrong Answer | H26: C++ | I26: N/A | J26: N/A | L26: 43/45 | M26: Submission 913013853 | N26: Yes
A27: 44996.411 | B27: 2023-03 | C27: 70 | D27: Climbing Stairs | E27: Easy | F27: DP: 1D / Linear | G27: Accepted | H27: C++ | I27: 0 ms | J27: 6.4 MB | K27: 100 | L27: 45/45 | M27: Submission 913014080 | N27: Yes
A28: 44996.601 | B28: 2023-03 | C28: 1377 | D28: Frog Position After T Seconds | E28: Hard | F28: Graph: General BFS/DFS | G28: Accepted | H28: C++ | I28: 15 ms | J28: 15.4 MB | K28: 11 | L28: 204/204 | M28: Submission 913125591 | N28: Yes
A29: 44996.642 | B29: 2023-03 | C29: 1377 | D29: Frog Position After T Seconds | E29: Hard | F29: Graph: General BFS/DFS | G29: Accepted | H29: C++ | I29: 26 ms | J29: 15.2 MB | K29: 5.1 | L29: 204/204 | M29: Submission 913148665 | N29: Yes
A30: 44996.71 | B30: 2023-03 | C30: 213 | D30: House Robber II | E30: Medium | F30: DP: 1D / Linear | G30: Wrong Answer | H30: C++ | I30: N/A | J30: N/A | L30: 68/75 | M30: Submission 913184731 | N30: Yes
A31: 44996.711 | B31: 2023-03 | C31: 213 | D31: House Robber II | E31: Medium | F31: DP: 1D / Linear | G31: Wrong Answer | H31: C++ | I31: N/A | J31: N/A | L31: 73/75 | M31: Submission 913185027 | N31: Yes
A32: 44996.712 | B32: 2023-03 | C32: 213 | D32: House Robber II | E32: Medium | F32: DP: 1D / Linear | G32: Accepted | H32: C++ | I32: 3 ms | J32: 8 MB | K32: 6.5 | L32: 75/75 | M32: Submission 913185817 | N32: Yes
A33: 44997.468 | B33: 2023-03 | C33: 64 | D33: Minimum Path Sum | E33: Medium | F33: DP: Grid / 2D | G33: Wrong Answer | H33: C++ | I33: N/A | J33: N/A | L33: 39/61 | M33: Submission 913633670 | N33: Yes
A34: 44997.47 | B34: 2023-03 | C34: 64 | D34: Minimum Path Sum | E34: Medium | F34: DP: Grid / 2D | G34: Accepted | H34: C++ | I34: 15 ms | J34: 10.1 MB | K34: 5.9 | L34: 61/61 | M34: Submission 913635348 | N34: Yes
A35: 44997.496 | B35: 2023-03 | C35: 741 | D35: Cherry Pickup | E35: Hard | F35: DP: Grid / 2D | G35: Wrong Answer | H35: Java | I35: N/A | J35: N/A | L35: 49/59 | M35: Submission 913652420 | N35: Yes
A36: 44997.604 | B36: 2023-03 | C36: 741 | D36: Cherry Pickup | E36: Hard | F36: DP: Grid / 2D | G36: Wrong Answer | H36: C++ | I36: N/A | J36: N/A | L36: 48/59 | M36: Submission 913718323 | N36: Yes
A37: 44997.605 | B37: 2023-03 | C37: 741 | D37: Cherry Pickup | E37: Hard | F37: DP: Grid / 2D | G37: Accepted | H37: C++ | I37: 832 ms | J37: 587.2 MB | K37: 5.1 | L37: 59/59 | M37: Submission 913718543 | N37: Yes
A38: 44997.656 | B38: 2023-03 | C38: 1463 | D38: Cherry Pickup II | E38: Hard | F38: DP: Grid / 2D | G38: Accepted | H38: C++ | I38: 565 ms | J38: 445.7 MB | K38: 5 | L38: 59/59 | M38: Submission 913747384 | N38: Yes
A39: 44997.709 | B39: 2023-03 | C39: 1463 | D39: Cherry Pickup II | E39: Hard | F39: DP: Grid / 2D | G39: Accepted | H39: C++ | I39: 142 ms | J39: 17.4 MB | K39: 5 | L39: 59/59 | M39: Submission 913776663 | N39: Yes
A40: 44997.715 | B40: 2023-03 | C40: 62 | D40: Unique Paths | E40: Medium | F40: DP: Grid / 2D | G40: Accepted | H40: C++ | I40: 0 ms | J40: 6.6 MB | K40: 100 | L40: 63/63 | M40: Submission 913779888 | N40: Yes
A41: 44997.726 | B41: 2023-03 | C41: 63 | D41: Unique Paths II | E41: Medium | F41: DP: Grid / 2D | G41: Wrong Answer | H41: C++ | I41: N/A | J41: N/A | L41: 37/41 | M41: Submission 913786083 | N41: Yes
A42: 44997.728 | B42: 2023-03 | C42: 63 | D42: Unique Paths II | E42: Medium | F42: DP: Grid / 2D | G42: Accepted | H42: C++ | I42: 0 ms | J42: 8 MB | K42: 100 | L42: 41/41 | M42: Submission 913786813 | N42: Yes
...

Sheet Pattern Summary
A1: Topic group | B1: Pattern | C1: Easy | D1: Medium | E1: Hard | F1: Total (your list) | G1: Other problems | H1: First-try AC rate (list) | I1: Avg submissions per problem (list) | J1: Failed attempts before AC (list)
A2: Arrays & Strings | B2: Arrays, Hashing & Sorting | C2: =COUNTIFS('Solved Problems'!$E$2:$E$278,$B2,'Solved Problems'!$D$2:$D$278,"Easy") | D2: =COUNTIFS('Solved Problems'!$E$2:$E$278,$B2,'Solved Problems'!$D$2:$D$278,"Medium") | E2: =COUNTIFS('Solved Problems'!$E$2:$E$278,$B2,'Solved Problems'!$D$2:$D$278,"Hard") | F2: =SUM(C2:E2) | G2: =COUNTIFS('Other Problems'!$E$2:$E$119,$B2) | H2: =IF(F2=0,"",COUNTIFS('Solved Problems'!$E$2:$E$278,$B2,'Solved Problems'!$P$2:$P$278,"Yes")/F2) | I2: =IF(F2=0,"",SUMIFS('Solved Problems'!$M$2:$M$278,'Solved Problems'!$E$2:$E$278,$B2)/F2) | J2: =SUMIFS('Solved Problems'!$O$2:$O$278,'Solved Problems'!$E$2:$E$278,$B2)
A3: Arrays & Strings | B3: Two Pointers | C3: =COUNTIFS('Solved Problems'!$E$2:$E$278,$B3,'Solved Problems'!$D$2:$D$278,"Easy") | D3: =COUNTIFS('Solved Problems'!$E$2:$E$278,$B3,'Solved Problems'!$D$2:$D$278,"Medium") | E3: =COUNTIFS('Solved Problems'!$E$2:$E$278,$B3,'Solved Problems'!$D$2:$D$278,"Hard") | F3: =SUM(C3:E3) | G3: =COUNTIFS('Other Problems'!$E$2:$E$119,$B3) | H3: =IF(F3=0,"",COUNTIFS('Solved Problems'!$E$2:$E$278,$B3,'Solved Problems'!$P$2:$P$278,"Yes")/F3) | I3: =IF(F3=0,"",SUMIFS('Solved Problems'!$M$2:$M$278,'Solved Problems'!$E$2:$E$278,$B3)/F3) | J3: =SUMIFS('Solved Problems'!$O$2:$O$278,'Solved Problems'!$E$2:$E$278,$B3)
A4: Arrays & Strings | B4: Sliding Window | C4: =COUNTIFS('Solved Problems'!$E$2:$E$278,$B4,'Solved Problems'!$D$2:$D$278,"Easy") | D4: =COUNTIFS('Solved Problems'!$E$2:$E$278,$B4,'Solved Problems'!$D$2:$D$278,"Medium") | E4: =COUNTIFS('Solved Problems'!$E$2:$E$278,$B4,'Solved Problems'!$D$2:$D$278,"Hard") | F4: =SUM(C4:E4) | G4: =COUNTIFS('Other Problems'!$E$2:$E$119,$B4) | H4: =IF(F4=0,"",COUNTIFS('Solved Problems'!$E$2:$E$278,$B4,'Solved Problems'!$P$2:$P$278,"Yes")/F4) | I4: =IF(F4=0,"",SUMIFS('Solved Problems'!$M$2:$M$278,'Solved Problems'!$E$2:$E$278,$B4)/F4) | J4: =SUMIFS('Solved Problems'!$O$2:$O$278,'Solved Problems'!$E$2:$E$278,$B4)
A5: Arrays & Strings | B5: Prefix Sum & Difference Array | C5: =COUNTIFS('Solved Problems'!$E$2:$E$278,$B5,'Solved Problems'!$D$2:$D$278,"Easy") | D5: =COUNTIFS('Solved Problems'!$E$2:$E$278,$B5,'Solved Problems'!$D$2:$D$278,"Medium") | E5: =COUNTIFS('Solved Problems'!$E$2:$E$278,$B5,'Solved Problems'!$D$2:$D$278,"Hard") | F5: =SUM(C5:E5) | G5: =COUNTIFS('Other Problems'!$E$2:$E$119,$B5) | H5: =IF(F5=0,"",COUNTIFS('Solved Problems'!$E$2:$E$278,$B5,'Solved Problems'!$P$2:$P$278,"Yes")/F5) | I5: =IF(F5=0,"",SUMIFS('Solved Problems'!$M$2:$M$278,'Solved Problems'!$E$2:$E$278,$B5)/F5) | J5: =SUMIFS('Solved Problems'!$O$2:$O$278,'Solved Problems'!$E$2:$E$278,$B5)
A6: Arrays & Strings | B6: Math & Bit Manipulation | C6: =COUNTIFS('Solved Problems'!$E$2:$E$278,$B6,'Solved Problems'!$D$2:$D$278,"Easy") | D6: =COUNTIFS('Solved Problems'!$E$2:$E$278,$B6,'Solved Problems'!$D$2:$D$278,"Medium") | E6: =COUNTIFS('Solved Problems'!$E$2:$E$278,$B6,'Solved Problems'!$D$2:$D$278,"Hard") | F6: =SUM(C6:E6) | G6: =COUNTIFS('Other Problems'!$E$2:$E$119,$B6) | H6: =IF(F6=0,"",COUNTIFS('Solved Problems'!$E$2:$E$278,$B6,'Solved Problems'!$P$2:$P$278,"Yes")/F6) | I6: =IF(F6=0,"",SUMIFS('Solved Problems'!$M$2:$M$278,'Solved Problems'!$E$2:$E$278,$B6)/F6) | J6: =SUMIFS('Solved Problems'!$O$2:$O$278,'Solved Problems'!$E$2:$E$278,$B6)
A7: Arrays & Strings | B7: Strings & Simulation | C7: =COUNTIFS('Solved Problems'!$E$2:$E$278,$B7,'Solved Problems'!$D$2:$D$278,"Easy") | D7: =COUNTIFS('Solved Problems'!$E$2:$E$278,$B7,'Solved Problems'!$D$2:$D$278,"Medium") | E7: =COUNTIFS('Solved Problems'!$E$2:$E$278,$B7,'Solved Problems'!$D$2:$D$278,"Hard") | F7: =SUM(C7:E7) | G7: =COUNTIFS('Other Problems'!$E$2:$E$119,$B7) | H7: =IF(F7=0,"",COUNTIFS('Solved Problems'!$E$2:$E$278,$B7,'Solved Problems'!$P$2:$P$278,"Yes")/F7) | I7: =IF(F7=0,"",SUMIFS('Solved Problems'!$M$2:$M$278,'Solved Problems'!$E$2:$E$278,$B7)/F7) | J7: =SUMIFS('Solved Problems'!$O$2:$O$278,'Solved Problems'!$E$2:$E$278,$B7)
A8: Searching | B8: Binary Search | C8: =COUNTIFS('Solved Problems'!$E$2:$E$278,$B8,'Solved Problems'!$D$2:$D$278,"Easy") | D8: =COUNTIFS('Solved Problems'!$E$2:$E$278,$B8,'Solved Problems'!$D$2:$D$278,"Medium") | E8: =COUNTIFS('Solved Problems'!$E$2:$E$278,$B8,'Solved Problems'!$D$2:$D$278,"Hard") | F8: =SUM(C8:E8) | G8: =COUNTIFS('Other Problems'!$E$2:$E$119,$B8) | H8: =IF(F8=0,"",COUNTIFS('Solved Problems'!$E$2:$E$278,$B8,'Solved Problems'!$P$2:$P$278,"Yes")/F8) | I8: =IF(F8=0,"",SUMIFS('Solved Problems'!$M$2:$M$278,'Solved Problems'!$E$2:$E$278,$B8)/F8) | J8: =SUMIFS('Solved Problems'!$O$2:$O$278,'Solved Problems'!$E$2:$E$278,$B8)
A9: Searching | B9: Binary Search on Answer | C9: =COUNTIFS('Solved Problems'!$E$2:$E$278,$B9,'Solved Problems'!$D$2:$D$278,"Easy") | D9: =COUNTIFS('Solved Problems'!$E$2:$E$278,$B9,'Solved Problems'!$D$2:$D$278,"Medium") | E9: =COUNTIFS('Solved Problems'!$E$2:$E$278,$B9,'Solved Problems'!$D$2:$D$278,"Hard") | F9: =SUM(C9:E9) | G9: =COUNTIFS('Other Problems'!$E$2:$E$119,$B9) | H9: =IF(F9=0,"",COUNTIFS('Solved Problems'!$E$2:$E$278,$B9,'Solved Problems'!$P$2:$P$278,"Yes")/F9) | I9: =IF(F9=0,"",SUMIFS('Solved Problems'!$M$2:$M$278,'Solved Problems'!$E$2:$E$278,$B9)/F9) | J9: =SUMIFS('Solved Problems'!$O$2:$O$278,'Solved Problems'!$E$2:$E$278,$B9)
A10: Stacks & Queues | B10: Stack | C10: =COUNTIFS('Solved Problems'!$E$2:$E$278,$B10,'Solved Problems'!$D$2:$D$278,"Easy") | D10: =COUNTIFS('Solved Problems'!$E$2:$E$278,$B10,'Solved Problems'!$D$2:$D$278,"Medium") | E10: =COUNTIFS('Solved Problems'!$E$2:$E$278,$B10,'Solved Problems'!$D$2:$D$278,"Hard") | F10: =SUM(C10:E10) | G10: =COUNTIFS('Other Problems'!$E$2:$E$119,$B10) | H10: =IF(F10=0,"",COUNTIFS('Solved Problems'!$E$2:$E$278,$B10,'Solved Problems'!$P$2:$P$278,"Yes")/F10) | I10: =IF(F10=0,"",SUMIFS('Solved Problems'!$M$2:$M$278,'Solved Problems'!$E$2:$E$278,$B10)/F10) | J10: =SUMIFS('Solved Problems'!$O$2:$O$278,'Solved Problems'!$E$2:$E$278,$B10)
A11: Stacks & Queues | B11: Monotonic Stack / Deque | C11: =COUNTIFS('Solved Problems'!$E$2:$E$278,$B11,'Solved Problems'!$D$2:$D$278,"Easy") | D11: =COUNTIFS('Solved Problems'!$E$2:$E$278,$B11,'Solved Problems'!$D$2:$D$278,"Medium") | E11: =COUNTIFS('Solved Problems'!$E$2:$E$278,$B11,'Solved Problems'!$D$2:$D$278,"Hard") | F11: =SUM(C11:E11) | G11: =COUNTIFS('Other Problems'!$E$2:$E$119,$B11) | H11: =IF(F11=0,"",COUNTIFS('Solved Problems'!$E$2:$E$278,$B11,'Solved Problems'!$P$2:$P$278,"Yes")/F11) | I11: =IF(F11=0,"",SUMIFS('Solved Problems'!$M$2:$M$278,'Solved Problems'!$E$2:$E$278,$B11)/F11) | J11: =SUMIFS('Solved Problems'!$O$2:$O$278,'Solved Problems'!$E$2:$E$278,$B11)
A12: Linked List | B12: Linked List | C12: =COUNTIFS('Solved Problems'!$E$2:$E$278,$B12,'Solved Problems'!$D$2:$D$278,"Easy") | D12: =COUNTIFS('Solved Problems'!$E$2:$E$278,$B12,'Solved Problems'!$D$2:$D$278,"Medium") | E12: =COUNTIFS('Solved Problems'!$E$2:$E$278,$B12,'Solved Problems'!$D$2:$D$278,"Hard") | F12: =SUM(C12:E12) | G12: =COUNTIFS('Other Problems'!$E$2:$E$119,$B12) | H12: =IF(F12=0,"",COUNTIFS('Solved Problems'!$E$2:$E$278,$B12,'Solved Problems'!$P$2:$P$278,"Yes")/F12) | I12: =IF(F12=0,"",SUMIFS('Solved Problems'!$M$2:$M$278,'Solved Problems'!$E$2:$E$278,$B12)/F12) | J12: =SUMIFS('Solved Problems'!$O$2:$O$278,'Solved Problems'!$E$2:$E$278,$B12)
A13: Trees | B13: Binary Tree (DFS & Recursion) | C13: =COUNTIFS('Solved Problems'!$E$2:$E$278,$B13,'Solved Problems'!$D$2:$D$278,"Easy") | D13: =COUNTIFS('Solved Problems'!$E$2:$E$278,$B13,'Solved Problems'!$D$2:$D$278,"Medium") | E13: =COUNTIFS('Solved Problems'!$E$2:$E$278,$B13,'Solved Problems'!$D$2:$D$278,"Hard") | F13: =SUM(C13:E13) | G13: =COUNTIFS('Other Problems'!$E$2:$E$119,$B13) | H13: =IF(F13=0,"",COUNTIFS('Solved Problems'!$E$2:$E$278,$B13,'Solved Problems'!$P$2:$P$278,"Yes")/F13) | I13: =IF(F13=0,"",SUMIFS('Solved Problems'!$M$2:$M$278,'Solved Problems'!$E$2:$E$278,$B13)/F13) | J13: =SUMIFS('Solved Problems'!$O$2:$O$278,'Solved Problems'!$E$2:$E$278,$B13)
... A36: Advanced Data Structures | B36: Segment Tree / BIT / Ordered Set | C36: =COUNTIFS('Solved Problems'!$E$2:$E$278,$B36,'Solved Problems'!$D$2:$D$278,"Easy") | D36: =COUNTIFS('Solved Problems'!$E$2:$E$278,$B36,'Solved Problems'!$D$2:$D$278,"Medium") | E36: =COUNTIFS('Solved Problems'!$E$2:$E$278,$B36,'Solved Problems'!$D$2:$D$278,"Hard") | F36: =SUM(C36:E36) | G36: =COUNTIFS('Other Problems'!$E$2:$E$119,$B36) | H36: =IF(F36=0,"",COUNTIFS('Solved Problems'!$E$2:$E$278,$B36,'Solved Problems'!$P$2:$P$278,"Yes")/F36) | I36: =IF(F36=0,"",SUMIFS('Solved Problems'!$M$2:$M$278,'Solved Problems'!$E$2:$E$278,$B36)/F36) | J36: =SUMIFS('Solved Problems'!$O$2:$O$278,'Solved Problems'!$E$2:$E$278,$B36)
B37: Total | C37: =SUM(C2:C36) | D37: =SUM(D2:D36) | E37: =SUM(E2:E36) | F37: =SUM(F2:F36) | G37: =SUM(G2:G36) | J37: =SUM(J2:J36)

Sheet Timeline
A1: Month | B1: Submissions | C1: Accepted | D1: Acceptance rate | E1: New problems solved (list) | F1: New problems solved (other) | G1: C++ subs | H1: Python subs | I1: Java subs
A2: 2023-03 | B2: =COUNTIFS(Submissions!$B$2:$B$1621,$A2) | C2: =COUNTIFS(Submissions!$B$2:$B$1621,$A2,Submissions!$G$2:$G$1621,"Accepted") | D2: =IF(B2=0,"",C2/B2) | E2: =COUNTIFS('Solved Problems'!$Y$2:$Y$278,$A2) | F2: =COUNTIFS('Other Problems'!$Y$2:$Y$119,$A2) | G2: =COUNTIFS(Submissions!$B$2:$B$1621,$A2,Submissions!$H$2:$H$1621,"C++") | H2: =COUNTIFS(Submissions!$B$2:$B$1621,$A2,Submissions!$H$2:$H$1621,"Python3")+COUNTIFS(Submissions!$B$2:$B$1621,$A2,Submissions!$H$2:$H$1621,"Python") | I2: =COUNTIFS(Submissions!$B$2:$B$1621,$A2,Submissions!$H$2:$H$1621,"Java")
A3: 2023-04 | B3: =COUNTIFS(Submissions!$B$2:$B$1621,$A3) | C3: =COUNTIFS(Submissions!$B$2:$B$1621,$A3,Submissions!$G$2:$G$1621,"Accepted") | D3: =IF(B3=0,"",C3/B3) | E3: =COUNTIFS('Solved Problems'!$Y$2:$Y$278,$A3) | F3: =COUNTIFS('Other Problems'!$Y$2:$Y$119,$A3) | G3: =COUNTIFS(Submissions!$B$2:$B$1621,$A3,Submissions!$H$2:$H$1621,"C++") | H3: =COUNTIFS(Submissions!$B$2:$B$1621,$A3,Submissions!$H$2:$H$1621,"Python3")+COUNTIFS(Submissions!$B$2:$B$1621,$A3,Submissions!$H$2:$H$1621,"Python") | I3: =COUNTIFS(Submissions!$B$2:$B$1621,$A3,Submissions!$H$2:$H$1621,"Java")
A4: 2023-05 | B4: =COUNTIFS(Submissions!$B$2:$B$1621,$A4) | C4: =COUNTIFS(Submissions!$B$2:$B$1621,$A4,Submissions!$G$2:$G$1621,"Accepted") | D4: =IF(B4=0,"",C4/B4) | E4: =COUNTIFS('Solved Problems'!$Y$2:$Y$278,$A4) | F4: =COUNTIFS('Other Problems'!$Y$2:$Y$119,$A4) | G4: =COUNTIFS(Submissions!$B$2:$B$1621,$A4,Submissions!$H$2:$H$1621,"C++") | H4: =COUNTIFS(Submissions!$B$2:$B$1621,$A4,Submissions!$H$2:$H$1621,"Python3")+COUNTIFS(Submissions!$B$2:$B$1621,$A4,Submissions!$H$2:$H$1621,"Python") | I4: =COUNTIFS(Submissions!$B$2:$B$1621,$A4,Submissions!$H$2:$H$1621,"Java")
A5: 2023-06 | B5: =COUNTIFS(Submissions!$B$2:$B$1621,$A5) | C5: =COUNTIFS(Submissions!$B$2:$B$1621,$A5,Submissions!$G$2:$G$1621,"Accepted") | D5: =IF(B5=0,"",C5/B5) | E5: =COUNTIFS('Solved Problems'!$Y$2:$Y$278,$A5) | F5: =COUNTIFS('Other Problems'!$Y$2:$Y$119,$A5) | G5: =COUNTIFS(Submissions!$B$2:$B$1621,$A5,Submissions!$H$2:$H$1621,"C++") | H5: =COUNTIFS(Submissions!$B$2:$B$1621,$A5,Submissions!$H$2:$H$1621,"Python3")+COUNTIFS(Submissions!$B$2:$B$1621,$A5,Submissions!$H$2:$H$1621,"Python") | I5: =COUNTIFS(Submissions!$B$2:$B$1621,$A5,Submissions!$H$2:$H$1621,"Java")
A6: 2023-07 | B6: =COUNTIFS(Submissions!$B$2:$B$1621,$A6) | C6: =COUNTIFS(Submissions!$B$2:$B$1621,$A6,Submissions!$G$2:$G$1621,"Accepted") | D6: =IF(B6=0,"",C6/B6) | E6: =COUNTIFS('Solved Problems'!$Y$2:$Y$278,$A6) | F6: =COUNTIFS('Other Problems'!$Y$2:$Y$119,$A6) | G6: =COUNTIFS(Submissions!$B$2:$B$1621,$A6,Submissions!$H$2:$H$1621,"C++") | H6: =COUNTIFS(Submissions!$B$2:$B$1621,$A6,Submissions!$H$2:$H$1621,"Python3")+COUNTIFS(Submissions!$B$2:$B$1621,$A6,Submissions!$H$2:$H$1621,"Python") | I6: =COUNTIFS(Submissions!$B$2:$B$1621,$A6,Submissions!$H$2:$H$1621,"Java")
A7: 2023-08 | B7: =COUNTIFS(Submissions!$B$2:$B$1621,$A7) | C7: =COUNTIFS(Submissions!$B$2:$B$1621,$A7,Submissions!$G$2:$G$1621,"Accepted") | D7: =IF(B7=0,"",C7/B7) | E7: =COUNTIFS('Solved Problems'!$Y$2:$Y$278,$A7) | F7: =COUNTIFS('Other Problems'!$Y$2:$Y$119,$A7) | G7: =COUNTIFS(Submissions!$B$2:$B$1621,$A7,Submissions!$H$2:$H$1621,"C++") | H7: =COUNTIFS(Submissions!$B$2:$B$1621,$A7,Submissions!$H$2:$H$1621,"Python3")+COUNTIFS(Submissions!$B$2:$B$1621,$A7,Submissions!$H$2:$H$1621,"Python") | I7: =COUNTIFS(Submissions!$B$2:$B$1621,$A7,Submissions!$H$2:$H$1621,"Java")
A8: 2023-09 | B8: =COUNTIFS(Submissions!$B$2:$B$1621,$A8) | C8: =COUNTIFS(Submissions!$B$2:$B$1621,$A8,Submissions!$G$2:$G$1621,"Accepted") | D8: =IF(B8=0,"",C8/B8) | E8: =COUNTIFS('Solved Problems'!$Y$2:$Y$278,$A8) | F8: =COUNTIFS('Other Problems'!$Y$2:$Y$119,$A8) | G8: =COUNTIFS(Submissions!$B$2:$B$1621,$A8,Submissions!$H$2:$H$1621,"C++") | H8: =COUNTIFS(Submissions!$B$2:$B$1621,$A8,Submissions!$H$2:$H$1621,"Python3")+COUNTIFS(Submissions!$B$2:$B$1621,$A8,Submissions!$H$2:$H$1621,"Python") | I8: =COUNTIFS(Submissions!$B$2:$B$1621,$A8,Submissions!$H$2:$H$1621,"Java")
A9: 2023-10 | B9: =COUNTIFS(Submissions!$B$2:$B$1621,$A9) | C9: =COUNTIFS(Submissions!$B$2:$B$1621,$A9,Submissions!$G$2:$G$1621,"Accepted") | D9: =IF(B9=0,"",C9/B9) | E9: =COUNTIFS('Solved Problems'!$Y$2:$Y$278,$A9) | F9: =COUNTIFS('Other Problems'!$Y$2:$Y$119,$A9) | G9: =COUNTIFS(Submissions!$B$2:$B$1621,$A9,Submissions!$H$2:$H$1621,"C++") | H9: =COUNTIFS(Submissions!$B$2:$B$1621,$A9,Submissions!$H$2:$H$1621,"Python3")+COUNTIFS(Submissions!$B$2:$B$1621,$A9,Submissions!$H$2:$H$1621,"Python") | I9: =COUNTIFS(Submissions!$B$2:$B$1621,$A9,Submissions!$H$2:$H$1621,"Java")
A10: 2023-11 | B10: =COUNTIFS(Submissions!$B$2:$B$1621,$A10) | C10: =COUNTIFS(Submissions!$B$2:$B$1621,$A10,Submissions!$G$2:$G$1621,"Accepted") | D10: =IF(B10=0,"",C10/B10) | E10: =COUNTIFS('Solved Problems'!$Y$2:$Y$278,$A10) | F10: =COUNTIFS('Other Problems'!$Y$2:$Y$119,$A10) | G10: =COUNTIFS(Submissions!$B$2:$B$1621,$A10,Submissions!$H$2:$H$1621,"C++") | H10: =COUNTIFS(Submissions!$B$2:$B$1621,$A10,Submissions!$H$2:$H$1621,"Python3")+COUNTIFS(Submissions!$B$2:$B$1621,$A10,Submissions!$H$2:$H$1621,"Python") | I10: =COUNTIFS(Submissions!$B$2:$B$1621,$A10,Submissions!$H$2:$H$1621,"Java")
